2024-11-11 19:12:33 ERROR Traceback (most recent call last):
  File "C:\Users\Saleem\AppData\Local\Programs\Python\Python312\Lib\site-packages\wandb\apis\normalize.py", line 41, in wrapper
    return func(*args, **kwargs)
           ^^^^^^^^^^^^^^^^^^^^^
  File "C:\Users\Saleem\AppData\Local\Programs\Python\Python312\Lib\site-packages\wandb\sdk\internal\internal_api.py", line 1065, in sweep
    raise ValueError(f"Sweep {entity}/{project}/{sweep} not found")
ValueError: Sweep tehcnionsaleem/LAB/pzpu5fqq not found

During handling of the above exception, another exception occurred:

Traceback (most recent call last):
  File "C:\Users\Saleem\AppData\Local\Programs\Python\Python312\Lib\site-packages\wandb\cli\cli.py", line 105, in wrapper
    return func(*args, **kwargs)
           ^^^^^^^^^^^^^^^^^^^^^
  File "C:\Users\Saleem\AppData\Local\Programs\Python\Python312\Lib\site-packages\wandb\cli\cli.py", line 1757, in agent
    wandb_agent.agent(sweep_id, entity=entity, project=project, count=count)
  File "C:\Users\Saleem\AppData\Local\Programs\Python\Python312\Lib\site-packages\wandb\wandb_agent.py", line 570, in agent
    return run_agent(
           ^^^^^^^^^^
  File "C:\Users\Saleem\AppData\Local\Programs\Python\Python312\Lib\site-packages\wandb\wandb_agent.py", line 528, in run_agent
    agent.run()
  File "C:\Users\Saleem\AppData\Local\Programs\Python\Python312\Lib\site-packages\wandb\wandb_agent.py", line 190, in run
    sweep_obj = self._api.sweep(self._sweep_id, "{}")
                ^^^^^^^^^^^^^^^^^^^^^^^^^^^^^^^^^^^^^
  File "C:\Users\Saleem\AppData\Local\Programs\Python\Python312\Lib\site-packages\wandb\apis\internal.py", line 126, in sweep
    return self.api.sweep(*args, **kwargs)
           ^^^^^^^^^^^^^^^^^^^^^^^^^^^^^^^
  File "C:\Users\Saleem\AppData\Local\Programs\Python\Python312\Lib\site-packages\wandb\apis\normalize.py", line 87, in wrapper
    raise CommError(message, err).with_traceback(sys.exc_info()[2])
  File "C:\Users\Saleem\AppData\Local\Programs\Python\Python312\Lib\site-packages\wandb\apis\normalize.py", line 41, in wrapper
    return func(*args, **kwargs)
           ^^^^^^^^^^^^^^^^^^^^^
  File "C:\Users\Saleem\AppData\Local\Programs\Python\Python312\Lib\site-packages\wandb\sdk\internal\internal_api.py", line 1065, in sweep
    raise ValueError(f"Sweep {entity}/{project}/{sweep} not found")
wandb.errors.CommError: Sweep tehcnionsaleem/LAB/pzpu5fqq not found

2024-11-11 19:13:13 ERROR Traceback (most recent call last):
  File "C:\Users\Saleem\AppData\Local\Programs\Python\Python312\Lib\site-packages\wandb\apis\normalize.py", line 41, in wrapper
    return func(*args, **kwargs)
           ^^^^^^^^^^^^^^^^^^^^^
  File "C:\Users\Saleem\AppData\Local\Programs\Python\Python312\Lib\site-packages\wandb\sdk\internal\internal_api.py", line 1065, in sweep
    raise ValueError(f"Sweep {entity}/{project}/{sweep} not found")
ValueError: Sweep tehcnionsaleem/LAB/pzpu5fqq not found

During handling of the above exception, another exception occurred:

Traceback (most recent call last):
  File "C:\Users\Saleem\AppData\Local\Programs\Python\Python312\Lib\site-packages\wandb\cli\cli.py", line 105, in wrapper
    return func(*args, **kwargs)
           ^^^^^^^^^^^^^^^^^^^^^
  File "C:\Users\Saleem\AppData\Local\Programs\Python\Python312\Lib\site-packages\wandb\cli\cli.py", line 1757, in agent
    wandb_agent.agent(sweep_id, entity=entity, project=project, count=count)
  File "C:\Users\Saleem\AppData\Local\Programs\Python\Python312\Lib\site-packages\wandb\wandb_agent.py", line 570, in agent
    return run_agent(
           ^^^^^^^^^^
  File "C:\Users\Saleem\AppData\Local\Programs\Python\Python312\Lib\site-packages\wandb\wandb_agent.py", line 528, in run_agent
    agent.run()
  File "C:\Users\Saleem\AppData\Local\Programs\Python\Python312\Lib\site-packages\wandb\wandb_agent.py", line 190, in run
    sweep_obj = self._api.sweep(self._sweep_id, "{}")
                ^^^^^^^^^^^^^^^^^^^^^^^^^^^^^^^^^^^^^
  File "C:\Users\Saleem\AppData\Local\Programs\Python\Python312\Lib\site-packages\wandb\apis\internal.py", line 126, in sweep
    return self.api.sweep(*args, **kwargs)
           ^^^^^^^^^^^^^^^^^^^^^^^^^^^^^^^
  File "C:\Users\Saleem\AppData\Local\Programs\Python\Python312\Lib\site-packages\wandb\apis\normalize.py", line 87, in wrapper
    raise CommError(message, err).with_traceback(sys.exc_info()[2])
  File "C:\Users\Saleem\AppData\Local\Programs\Python\Python312\Lib\site-packages\wandb\apis\normalize.py", line 41, in wrapper
    return func(*args, **kwargs)
           ^^^^^^^^^^^^^^^^^^^^^
  File "C:\Users\Saleem\AppData\Local\Programs\Python\Python312\Lib\site-packages\wandb\sdk\internal\internal_api.py", line 1065, in sweep
    raise ValueError(f"Sweep {entity}/{project}/{sweep} not found")
wandb.errors.CommError: Sweep tehcnionsaleem/LAB/pzpu5fqq not found

2024-11-11 19:15:01 ERROR Traceback (most recent call last):
  File "C:\Users\Saleem\AppData\Local\Programs\Python\Python312\Lib\site-packages\wandb\apis\normalize.py", line 41, in wrapper
    return func(*args, **kwargs)
           ^^^^^^^^^^^^^^^^^^^^^
  File "C:\Users\Saleem\AppData\Local\Programs\Python\Python312\Lib\site-packages\wandb\sdk\internal\internal_api.py", line 1065, in sweep
    raise ValueError(f"Sweep {entity}/{project}/{sweep} not found")
ValueError: Sweep tehcnionsaleem/LAB/pzpu5fqq not found

During handling of the above exception, another exception occurred:

Traceback (most recent call last):
  File "C:\Users\Saleem\AppData\Local\Programs\Python\Python312\Lib\site-packages\wandb\cli\cli.py", line 105, in wrapper
    return func(*args, **kwargs)
           ^^^^^^^^^^^^^^^^^^^^^
  File "C:\Users\Saleem\AppData\Local\Programs\Python\Python312\Lib\site-packages\wandb\cli\cli.py", line 1757, in agent
    wandb_agent.agent(sweep_id, entity=entity, project=project, count=count)
  File "C:\Users\Saleem\AppData\Local\Programs\Python\Python312\Lib\site-packages\wandb\wandb_agent.py", line 570, in agent
    return run_agent(
           ^^^^^^^^^^
  File "C:\Users\Saleem\AppData\Local\Programs\Python\Python312\Lib\site-packages\wandb\wandb_agent.py", line 528, in run_agent
    agent.run()
  File "C:\Users\Saleem\AppData\Local\Programs\Python\Python312\Lib\site-packages\wandb\wandb_agent.py", line 190, in run
    sweep_obj = self._api.sweep(self._sweep_id, "{}")
                ^^^^^^^^^^^^^^^^^^^^^^^^^^^^^^^^^^^^^
  File "C:\Users\Saleem\AppData\Local\Programs\Python\Python312\Lib\site-packages\wandb\apis\internal.py", line 126, in sweep
    return self.api.sweep(*args, **kwargs)
           ^^^^^^^^^^^^^^^^^^^^^^^^^^^^^^^
  File "C:\Users\Saleem\AppData\Local\Programs\Python\Python312\Lib\site-packages\wandb\apis\normalize.py", line 87, in wrapper
    raise CommError(message, err).with_traceback(sys.exc_info()[2])
  File "C:\Users\Saleem\AppData\Local\Programs\Python\Python312\Lib\site-packages\wandb\apis\normalize.py", line 41, in wrapper
    return func(*args, **kwargs)
           ^^^^^^^^^^^^^^^^^^^^^
  File "C:\Users\Saleem\AppData\Local\Programs\Python\Python312\Lib\site-packages\wandb\sdk\internal\internal_api.py", line 1065, in sweep
    raise ValueError(f"Sweep {entity}/{project}/{sweep} not found")
wandb.errors.CommError: Sweep tehcnionsaleem/LAB/pzpu5fqq not found

2024-11-11 19:16:18 ERROR Traceback (most recent call last):
  File "C:\Users\Saleem\AppData\Local\Programs\Python\Python312\Lib\site-packages\wandb\apis\normalize.py", line 41, in wrapper
    return func(*args, **kwargs)
           ^^^^^^^^^^^^^^^^^^^^^
  File "C:\Users\Saleem\AppData\Local\Programs\Python\Python312\Lib\site-packages\wandb\sdk\internal\internal_api.py", line 1065, in sweep
    raise ValueError(f"Sweep {entity}/{project}/{sweep} not found")
ValueError: Sweep tehcnionsaleem-org/LAB/pzpu5fqq not found

During handling of the above exception, another exception occurred:

Traceback (most recent call last):
  File "C:\Users\Saleem\AppData\Local\Programs\Python\Python312\Lib\site-packages\wandb\cli\cli.py", line 105, in wrapper
    return func(*args, **kwargs)
           ^^^^^^^^^^^^^^^^^^^^^
  File "C:\Users\Saleem\AppData\Local\Programs\Python\Python312\Lib\site-packages\wandb\cli\cli.py", line 1757, in agent
    wandb_agent.agent(sweep_id, entity=entity, project=project, count=count)
  File "C:\Users\Saleem\AppData\Local\Programs\Python\Python312\Lib\site-packages\wandb\wandb_agent.py", line 570, in agent
    return run_agent(
           ^^^^^^^^^^
  File "C:\Users\Saleem\AppData\Local\Programs\Python\Python312\Lib\site-packages\wandb\wandb_agent.py", line 528, in run_agent
    agent.run()
  File "C:\Users\Saleem\AppData\Local\Programs\Python\Python312\Lib\site-packages\wandb\wandb_agent.py", line 190, in run
    sweep_obj = self._api.sweep(self._sweep_id, "{}")
                ^^^^^^^^^^^^^^^^^^^^^^^^^^^^^^^^^^^^^
  File "C:\Users\Saleem\AppData\Local\Programs\Python\Python312\Lib\site-packages\wandb\apis\internal.py", line 126, in sweep
    return self.api.sweep(*args, **kwargs)
           ^^^^^^^^^^^^^^^^^^^^^^^^^^^^^^^
  File "C:\Users\Saleem\AppData\Local\Programs\Python\Python312\Lib\site-packages\wandb\apis\normalize.py", line 87, in wrapper
    raise CommError(message, err).with_traceback(sys.exc_info()[2])
  File "C:\Users\Saleem\AppData\Local\Programs\Python\Python312\Lib\site-packages\wandb\apis\normalize.py", line 41, in wrapper
    return func(*args, **kwargs)
           ^^^^^^^^^^^^^^^^^^^^^
  File "C:\Users\Saleem\AppData\Local\Programs\Python\Python312\Lib\site-packages\wandb\sdk\internal\internal_api.py", line 1065, in sweep
    raise ValueError(f"Sweep {entity}/{project}/{sweep} not found")
wandb.errors.CommError: Sweep tehcnionsaleem-org/LAB/pzpu5fqq not found

2024-11-11 19:17:03 INFO Running runs: []
2024-11-11 19:17:04 INFO Agent received command: run
2024-11-11 19:17:04 INFO Agent starting run with config:
	AL4GE: False
	budget_per_iter: 8
	classifier: LogisticRegression
	coef: [True, True, False, False]
	dataset: lab_dataset_2000.pkl
	gnn_epochs: 5
	hidden_size: 32
	iterations: 100
	n_clusters: 2
	quantile: 0.1
	sim_metric: cosine
	uncertainty_measures: ['entropy_e', 'density_kmean', 'pagerank', 'area_variance']
	use_gnn: True
	wandb: 1
2024-11-11 19:17:04 INFO About to run command: python  --AL4GE=False --budget_per_iter=8 --classifier=LogisticRegression "--coef=[True, True, False, False]" --dataset=lab_dataset_2000.pkl --gnn_epochs=5 --hidden_size=32 --iterations=100 --n_clusters=2 --quantile=0.1 --sim_metric=cosine "--uncertainty_measures=['entropy_e', 'density_kmean', 'pagerank', 'area_variance']" --use_gnn=True --wandb=1
2024-11-11 19:17:09 INFO Running runs: ['s4a6nbk0']
2024-11-11 19:17:09 INFO Cleaning up finished run: s4a6nbk0
2024-11-11 19:17:10 INFO Agent received command: run
2024-11-11 19:17:10 INFO Agent starting run with config:
	AL4GE: False
	budget_per_iter: 8
	classifier: LogisticRegression
	coef: [True, True, False, False]
	dataset: lab_dataset_2000.pkl
	gnn_epochs: 5
	hidden_size: 32
	iterations: 100
	n_clusters: 2
	quantile: 0.1
	sim_metric: euclidean
	uncertainty_measures: ['entropy_e', 'density_kmean', 'pagerank', 'area_variance']
	use_gnn: True
	wandb: 1
2024-11-11 19:17:10 INFO About to run command: python  --AL4GE=False --budget_per_iter=8 --classifier=LogisticRegression "--coef=[True, True, False, False]" --dataset=lab_dataset_2000.pkl --gnn_epochs=5 --hidden_size=32 --iterations=100 --n_clusters=2 --quantile=0.1 --sim_metric=euclidean "--uncertainty_measures=['entropy_e', 'density_kmean', 'pagerank', 'area_variance']" --use_gnn=True --wandb=1
2024-11-11 19:19:20 INFO Running runs: []
2024-11-11 19:19:20 INFO Agent received command: run
2024-11-11 19:19:20 INFO Agent starting run with config:
	AL4GE: False
	budget_per_iter: 8
	classifier: LogisticRegression
	coef: [True, True, False, False]
	dataset: lab_dataset_2000.pkl
	gnn_epochs: 5
	hidden_size: 32
	iterations: 100
	n_clusters: 2
	quantile: 0.1
	sim_metric: cosine
	uncertainty_measures: ['entropy_e', 'density_kmean', 'pagerank', 'area_variance']
	use_gnn: True
	wandb: 1
2024-11-11 19:19:20 INFO About to run command: python main.py --AL4GE=False --budget_per_iter=8 --classifier=LogisticRegression "--coef=[True, True, False, False]" --dataset=lab_dataset_2000.pkl --gnn_epochs=5 --hidden_size=32 --iterations=100 --n_clusters=2 --quantile=0.1 --sim_metric=cosine "--uncertainty_measures=['entropy_e', 'density_kmean', 'pagerank', 'area_variance']" --use_gnn=True --wandb=1
2024-11-11 19:19:25 INFO Running runs: ['wdasb3ii']
2024-11-11 19:19:31 INFO Cleaning up finished run: wdasb3ii
2024-11-11 19:19:31 INFO Agent received command: run
2024-11-11 19:19:31 INFO Agent starting run with config:
	AL4GE: False
	budget_per_iter: 8
	classifier: LogisticRegression
	coef: [True, True, False, False]
	dataset: lab_dataset_2000.pkl
	gnn_epochs: 5
	hidden_size: 32
	iterations: 100
	n_clusters: 2
	quantile: 0.1
	sim_metric: euclidean
	uncertainty_measures: ['entropy_e', 'density_kmean', 'pagerank', 'area_variance']
	use_gnn: True
	wandb: 1
2024-11-11 19:19:31 INFO About to run command: python main.py --AL4GE=False --budget_per_iter=8 --classifier=LogisticRegression "--coef=[True, True, False, False]" --dataset=lab_dataset_2000.pkl --gnn_epochs=5 --hidden_size=32 --iterations=100 --n_clusters=2 --quantile=0.1 --sim_metric=euclidean "--uncertainty_measures=['entropy_e', 'density_kmean', 'pagerank', 'area_variance']" --use_gnn=True --wandb=1
2024-11-11 19:20:28 INFO Running runs: []
2024-11-11 19:20:28 INFO Agent received command: run
2024-11-11 19:20:28 INFO Agent starting run with config:
	AL4GE: False
	budget_per_iter: 8
	classifier: LogisticRegression
	coef: [True, True, False, False]
	dataset: lab_dataset_2000.pkl
	gnn_epochs: 5
	gnn_hidden: 32
	iterations: 100
	n_clusters: 2
	quantile: 0.1
	sim_metric: cosine
	uncertainty_measures: ['entropy_e', 'density_kmean', 'pagerank', 'area_variance']
	use_gnn: True
	wandb: 1
2024-11-11 19:20:28 INFO About to run command: python main.py --AL4GE=False --budget_per_iter=8 --classifier=LogisticRegression "--coef=[True, True, False, False]" --dataset=lab_dataset_2000.pkl --gnn_epochs=5 --gnn_hidden=32 --iterations=100 --n_clusters=2 --quantile=0.1 --sim_metric=cosine "--uncertainty_measures=['entropy_e', 'density_kmean', 'pagerank', 'area_variance']" --use_gnn=True --wandb=1
2024-11-11 19:20:33 INFO Running runs: ['u06lljm4']
2024-11-11 19:22:53 INFO Cleaning up finished run: u06lljm4
2024-11-11 19:23:03 INFO Agent received command: run
2024-11-11 19:23:03 INFO Agent starting run with config:
	AL4GE: False
	budget_per_iter: 8
	classifier: LogisticRegression
	coef: [True, True, False, False]
	dataset: lab_dataset_2000.pkl
	gnn_epochs: 5
	gnn_hidden: 32
	iterations: 100
	n_clusters: 2
	quantile: 0.1
	sim_metric: euclidean
	uncertainty_measures: ['entropy_e', 'density_kmean', 'pagerank', 'area_variance']
	use_gnn: True
	wandb: 1
2024-11-11 19:23:03 INFO About to run command: python main.py --AL4GE=False --budget_per_iter=8 --classifier=LogisticRegression "--coef=[True, True, False, False]" --dataset=lab_dataset_2000.pkl --gnn_epochs=5 --gnn_hidden=32 --iterations=100 --n_clusters=2 --quantile=0.1 --sim_metric=euclidean "--uncertainty_measures=['entropy_e', 'density_kmean', 'pagerank', 'area_variance']" --use_gnn=True --wandb=1
2024-11-11 19:23:08 INFO Running runs: ['h772o95y']
2024-11-11 19:27:26 ERROR Traceback (most recent call last):
  File "C:\Users\Saleem\AppData\Local\Programs\Python\Python312\Lib\site-packages\wandb\apis\normalize.py", line 41, in wrapper
    return func(*args, **kwargs)
           ^^^^^^^^^^^^^^^^^^^^^
  File "C:\Users\Saleem\AppData\Local\Programs\Python\Python312\Lib\site-packages\wandb\sdk\internal\internal_api.py", line 1065, in sweep
    raise ValueError(f"Sweep {entity}/{project}/{sweep} not found")
ValueError: Sweep majedbishara-technion-israel-institute-of-technology/Bsc_Finale/icq79pfs not found

During handling of the above exception, another exception occurred:

Traceback (most recent call last):
  File "C:\Users\Saleem\AppData\Local\Programs\Python\Python312\Lib\site-packages\wandb\cli\cli.py", line 105, in wrapper
    return func(*args, **kwargs)
           ^^^^^^^^^^^^^^^^^^^^^
  File "C:\Users\Saleem\AppData\Local\Programs\Python\Python312\Lib\site-packages\wandb\cli\cli.py", line 1757, in agent
    wandb_agent.agent(sweep_id, entity=entity, project=project, count=count)
  File "C:\Users\Saleem\AppData\Local\Programs\Python\Python312\Lib\site-packages\wandb\wandb_agent.py", line 570, in agent
    return run_agent(
           ^^^^^^^^^^
  File "C:\Users\Saleem\AppData\Local\Programs\Python\Python312\Lib\site-packages\wandb\wandb_agent.py", line 528, in run_agent
    agent.run()
  File "C:\Users\Saleem\AppData\Local\Programs\Python\Python312\Lib\site-packages\wandb\wandb_agent.py", line 190, in run
    sweep_obj = self._api.sweep(self._sweep_id, "{}")
                ^^^^^^^^^^^^^^^^^^^^^^^^^^^^^^^^^^^^^
  File "C:\Users\Saleem\AppData\Local\Programs\Python\Python312\Lib\site-packages\wandb\apis\internal.py", line 126, in sweep
    return self.api.sweep(*args, **kwargs)
           ^^^^^^^^^^^^^^^^^^^^^^^^^^^^^^^
  File "C:\Users\Saleem\AppData\Local\Programs\Python\Python312\Lib\site-packages\wandb\apis\normalize.py", line 87, in wrapper
    raise CommError(message, err).with_traceback(sys.exc_info()[2])
  File "C:\Users\Saleem\AppData\Local\Programs\Python\Python312\Lib\site-packages\wandb\apis\normalize.py", line 41, in wrapper
    return func(*args, **kwargs)
           ^^^^^^^^^^^^^^^^^^^^^
  File "C:\Users\Saleem\AppData\Local\Programs\Python\Python312\Lib\site-packages\wandb\sdk\internal\internal_api.py", line 1065, in sweep
    raise ValueError(f"Sweep {entity}/{project}/{sweep} not found")
wandb.errors.CommError: Sweep majedbishara-technion-israel-institute-of-technology/Bsc_Finale/icq79pfs not found

2024-11-11 19:27:40 ERROR Traceback (most recent call last):
  File "C:\Users\Saleem\AppData\Local\Programs\Python\Python312\Lib\site-packages\wandb\apis\normalize.py", line 41, in wrapper
    return func(*args, **kwargs)
           ^^^^^^^^^^^^^^^^^^^^^
  File "C:\Users\Saleem\AppData\Local\Programs\Python\Python312\Lib\site-packages\wandb\sdk\internal\internal_api.py", line 1065, in sweep
    raise ValueError(f"Sweep {entity}/{project}/{sweep} not found")
ValueError: Sweep majedbishara-technion-israel-institute-of-technology/Bsc_Finale/icq79pfs not found

During handling of the above exception, another exception occurred:

Traceback (most recent call last):
  File "C:\Users\Saleem\AppData\Local\Programs\Python\Python312\Lib\site-packages\wandb\cli\cli.py", line 105, in wrapper
    return func(*args, **kwargs)
           ^^^^^^^^^^^^^^^^^^^^^
  File "C:\Users\Saleem\AppData\Local\Programs\Python\Python312\Lib\site-packages\wandb\cli\cli.py", line 1757, in agent
    wandb_agent.agent(sweep_id, entity=entity, project=project, count=count)
  File "C:\Users\Saleem\AppData\Local\Programs\Python\Python312\Lib\site-packages\wandb\wandb_agent.py", line 570, in agent
    return run_agent(
           ^^^^^^^^^^
  File "C:\Users\Saleem\AppData\Local\Programs\Python\Python312\Lib\site-packages\wandb\wandb_agent.py", line 528, in run_agent
    agent.run()
  File "C:\Users\Saleem\AppData\Local\Programs\Python\Python312\Lib\site-packages\wandb\wandb_agent.py", line 190, in run
    sweep_obj = self._api.sweep(self._sweep_id, "{}")
                ^^^^^^^^^^^^^^^^^^^^^^^^^^^^^^^^^^^^^
  File "C:\Users\Saleem\AppData\Local\Programs\Python\Python312\Lib\site-packages\wandb\apis\internal.py", line 126, in sweep
    return self.api.sweep(*args, **kwargs)
           ^^^^^^^^^^^^^^^^^^^^^^^^^^^^^^^
  File "C:\Users\Saleem\AppData\Local\Programs\Python\Python312\Lib\site-packages\wandb\apis\normalize.py", line 87, in wrapper
    raise CommError(message, err).with_traceback(sys.exc_info()[2])
  File "C:\Users\Saleem\AppData\Local\Programs\Python\Python312\Lib\site-packages\wandb\apis\normalize.py", line 41, in wrapper
    return func(*args, **kwargs)
           ^^^^^^^^^^^^^^^^^^^^^
  File "C:\Users\Saleem\AppData\Local\Programs\Python\Python312\Lib\site-packages\wandb\sdk\internal\internal_api.py", line 1065, in sweep
    raise ValueError(f"Sweep {entity}/{project}/{sweep} not found")
wandb.errors.CommError: Sweep majedbishara-technion-israel-institute-of-technology/Bsc_Finale/icq79pfs not found

2024-11-11 19:29:25 ERROR Traceback (most recent call last):
  File "C:\Users\Saleem\AppData\Local\Programs\Python\Python312\Lib\site-packages\wandb\apis\normalize.py", line 41, in wrapper
    return func(*args, **kwargs)
           ^^^^^^^^^^^^^^^^^^^^^
  File "C:\Users\Saleem\AppData\Local\Programs\Python\Python312\Lib\site-packages\wandb\sdk\internal\internal_api.py", line 1065, in sweep
    raise ValueError(f"Sweep {entity}/{project}/{sweep} not found")
ValueError: Sweep majedbishara-technion-israel-institute-of-technology/Bsc_Finale/icq79pfs not found

During handling of the above exception, another exception occurred:

Traceback (most recent call last):
  File "C:\Users\Saleem\AppData\Local\Programs\Python\Python312\Lib\site-packages\wandb\cli\cli.py", line 105, in wrapper
    return func(*args, **kwargs)
           ^^^^^^^^^^^^^^^^^^^^^
  File "C:\Users\Saleem\AppData\Local\Programs\Python\Python312\Lib\site-packages\wandb\cli\cli.py", line 1757, in agent
    wandb_agent.agent(sweep_id, entity=entity, project=project, count=count)
  File "C:\Users\Saleem\AppData\Local\Programs\Python\Python312\Lib\site-packages\wandb\wandb_agent.py", line 570, in agent
    return run_agent(
           ^^^^^^^^^^
  File "C:\Users\Saleem\AppData\Local\Programs\Python\Python312\Lib\site-packages\wandb\wandb_agent.py", line 528, in run_agent
    agent.run()
  File "C:\Users\Saleem\AppData\Local\Programs\Python\Python312\Lib\site-packages\wandb\wandb_agent.py", line 190, in run
    sweep_obj = self._api.sweep(self._sweep_id, "{}")
                ^^^^^^^^^^^^^^^^^^^^^^^^^^^^^^^^^^^^^
  File "C:\Users\Saleem\AppData\Local\Programs\Python\Python312\Lib\site-packages\wandb\apis\internal.py", line 126, in sweep
    return self.api.sweep(*args, **kwargs)
           ^^^^^^^^^^^^^^^^^^^^^^^^^^^^^^^
  File "C:\Users\Saleem\AppData\Local\Programs\Python\Python312\Lib\site-packages\wandb\apis\normalize.py", line 87, in wrapper
    raise CommError(message, err).with_traceback(sys.exc_info()[2])
  File "C:\Users\Saleem\AppData\Local\Programs\Python\Python312\Lib\site-packages\wandb\apis\normalize.py", line 41, in wrapper
    return func(*args, **kwargs)
           ^^^^^^^^^^^^^^^^^^^^^
  File "C:\Users\Saleem\AppData\Local\Programs\Python\Python312\Lib\site-packages\wandb\sdk\internal\internal_api.py", line 1065, in sweep
    raise ValueError(f"Sweep {entity}/{project}/{sweep} not found")
wandb.errors.CommError: Sweep majedbishara-technion-israel-institute-of-technology/Bsc_Finale/icq79pfs not found

2024-11-11 19:29:43 ERROR Traceback (most recent call last):
  File "C:\Users\Saleem\AppData\Local\Programs\Python\Python312\Lib\site-packages\wandb\apis\normalize.py", line 41, in wrapper
    return func(*args, **kwargs)
           ^^^^^^^^^^^^^^^^^^^^^
  File "C:\Users\Saleem\AppData\Local\Programs\Python\Python312\Lib\site-packages\wandb\sdk\internal\internal_api.py", line 1065, in sweep
    raise ValueError(f"Sweep {entity}/{project}/{sweep} not found")
ValueError: Sweep majedbishara-technion-israel-institute-of-technology/Bsc_Finale/xxgoqe2k not found

During handling of the above exception, another exception occurred:

Traceback (most recent call last):
  File "C:\Users\Saleem\AppData\Local\Programs\Python\Python312\Lib\site-packages\wandb\cli\cli.py", line 105, in wrapper
    return func(*args, **kwargs)
           ^^^^^^^^^^^^^^^^^^^^^
  File "C:\Users\Saleem\AppData\Local\Programs\Python\Python312\Lib\site-packages\wandb\cli\cli.py", line 1757, in agent
    wandb_agent.agent(sweep_id, entity=entity, project=project, count=count)
  File "C:\Users\Saleem\AppData\Local\Programs\Python\Python312\Lib\site-packages\wandb\wandb_agent.py", line 570, in agent
    return run_agent(
           ^^^^^^^^^^
  File "C:\Users\Saleem\AppData\Local\Programs\Python\Python312\Lib\site-packages\wandb\wandb_agent.py", line 528, in run_agent
    agent.run()
  File "C:\Users\Saleem\AppData\Local\Programs\Python\Python312\Lib\site-packages\wandb\wandb_agent.py", line 190, in run
    sweep_obj = self._api.sweep(self._sweep_id, "{}")
                ^^^^^^^^^^^^^^^^^^^^^^^^^^^^^^^^^^^^^
  File "C:\Users\Saleem\AppData\Local\Programs\Python\Python312\Lib\site-packages\wandb\apis\internal.py", line 126, in sweep
    return self.api.sweep(*args, **kwargs)
           ^^^^^^^^^^^^^^^^^^^^^^^^^^^^^^^
  File "C:\Users\Saleem\AppData\Local\Programs\Python\Python312\Lib\site-packages\wandb\apis\normalize.py", line 87, in wrapper
    raise CommError(message, err).with_traceback(sys.exc_info()[2])
  File "C:\Users\Saleem\AppData\Local\Programs\Python\Python312\Lib\site-packages\wandb\apis\normalize.py", line 41, in wrapper
    return func(*args, **kwargs)
           ^^^^^^^^^^^^^^^^^^^^^
  File "C:\Users\Saleem\AppData\Local\Programs\Python\Python312\Lib\site-packages\wandb\sdk\internal\internal_api.py", line 1065, in sweep
    raise ValueError(f"Sweep {entity}/{project}/{sweep} not found")
wandb.errors.CommError: Sweep majedbishara-technion-israel-institute-of-technology/Bsc_Finale/xxgoqe2k not found

